---
# Tasks for for testing feature to solve Issue 436

- name: Insert a record into a collection
  community.mongodb.mongodb_shell:
    login_user: '{{ mongodb_admin_user }}'
    login_password: '{{ mongodb_admin_password }}'
    login_port: 3001
    debug: yes
    db: "test"
    eval: 'db.hosts.insertOne({"_id": "first_record"})'
    mongo_cmd: "auto"
  register: first_insert

- assert:
    that: 
      - first_insert.changed

- assert:
    that:
      - "first_insert.transformed_output == {\"acknowledged\":true,\"insertedIds\":{\"0\":\"first_record\"}}"

- name: Insert a duplicate record into a collection - mongo shell does not throw an error so neither do we (mongosh does throw an error)
  community.mongodb.mongodb_shell:
    login_user: '{{ mongodb_admin_user }}'
    login_password: '{{ mongodb_admin_password }}'
    login_port: 3001
    debug: yes
    db: "test"
    eval: 'db.hosts.insertOne({"_id": "first_record"})'
    mongo_cmd: "auto"
  register: first_insert_duplicate

- assert:
    that: 
      - first_insert_duplicate.changed
      
- assert:
    that: 
      - first_insert_duplicate.out.startswith('WriteResult({')
      - "first_insert_duplicate.transformed_output == {\"nInserted\": 0, \"writeError\": {\"code\": 11000, \"errmsg\": \"E11000 duplicate key error collection: test.hosts index: _id_ dup key: { _id: \\\"first_record\\\" }\"}}"